Workbook

Sheet Resumen
A1: 🐔 POLLISIMO 🐔
A2: Panel de control del emprendimiento
B4: 💰 Total Ventas (entregados) | D4: 🧾 Total Gastos en Insumos
B5: =SUMIFS(Ventas!$G$5:$G$49,Ventas!$I$5:$I$49,"Entregado") -> 437700 | D5: =SUM(Compras!$E$5:$E$44) -> 390515
B7: 💵 Ingresos en Efectivo | D7: 🏦 Ingresos por Transferencia
B8: =SUMIFS(Ventas!$G$5:$G$49,Ventas!$I$5:$I$49,"Entregado",Ventas!$H$5:$H$49,"Efectivo") -> 131800 | D8: =SUMIFS(Ventas!$G$5:$G$49,Ventas!$I$5:$I$49,"Entregado",Ventas!$H$5:$H$49,"Transferencia") -> 294400
B10: 📈 Ganancia Neta Estimada | D10: 📦 Pedidos Pendientes/Reservados
B11: =B5-D5 -> 47185 | D11: =COUNTIFS(Ventas!$I$5:$I$49,"Pendiente")+COUNTIFS(Ventas!$I$5:$I$49,"Reservado") -> 1
B13: 🍱 Bandejas Disponibles | D13: ⚠️ Insumos con Stock Bajo
B14: =SUM(Produccion!G46:G51) -> 27 | D14: =COUNTIF(Stock!$H$5:$H$19,"BAJO") -> 4
B16: ⚖️ Kilos Disponibles | D16: 🗓️ Última actualización
B17: =SUM(Produccion!D46:D51) -> -46.059 | D17: 46220
B20: Este panel se actualiza solo a medida que cargás datos en las hojas Ventas, Compras, Stock y Producción. No hace falta tocar nada acá.
B22: 📑 Guía rápida de las hojas:
B23: • Productos | C23: Precios por kilo y costos de cada producto.
B24: • Stock | C24: Insumos: lo que tenés, lo que compraste y lo que usaste. Se actualiza solo.
B25: • Ventas | C25: Cada bandeja vendida o reservada: peso, precio calculado y estado.
B26: • Compras | C26: Cada compra de insumos. Si 'Afecta Stock' = Sí, suma al stock.
B27: • Producción | C27: Insumos usados, costo, bandejas/kilos obtenidos y stock disponible.

Sheet Productos
A1: POLLISIMO 🐔 - Productos y Precios
A2: Cargá acá tus productos con precio por kilo y costo estimado. Esto alimenta el resto del archivo (en Ventas, el precio se calcula solo según el peso de cada bandeja).
A4: Producto | B4: Unidad | C4: Precio por Kg | D4: Costo Estimado x Kg | E4: Margen | F4: Notas
A5: Milanesa de pollo | B5: kg | C5: 9500 | D5: 4200 | E5: =IFERROR((C5-D5)/C5,"") -> 0.55789474
E6: =IFERROR((C6-D6)/C6,"")
E7: =IFERROR((C7-D7)/C7,"")
E8: =IFERROR((C8-D8)/C8,"")
E9: =IFERROR((C9-D9)/C9,"")
E10: =IFERROR((C10-D10)/C10,"")
A12: 🟡 Celdas amarillas = completar vos. Las demás se calculan solas.

Sheet Stock
A1: POLLISIMO 🐔 - Stock de Insumos
A2: Stock Inicial = tu último conteo real. Compras y Producción se descuentan/suman solas (según la columna 'Afecta Stock' de esas hojas). Stock Actual = Inicial + Compras − Usado en Producción.
A4: Insumo | B4: Unidad | C4: Stock Inicial | D4: Compras (automático) | E4: Usado en Producción (automático) | F4: Stock Actual | G4: Stock Mínimo | H4: Estado | I4: Costo Unitario | J4: Valor en Stock
A5: Pechuga de pollo | B5: kg | C5: 15 | D5: =IFERROR(SUMIFS(Compras!$C$5:$C$44,Compras!$B$5:$B$44,A5,Compras!$H$5:$H$44,"Sí"),0) -> 0 | E5: =IFERROR(SUMIF(Produccion!$D$6:$D$39,"Sí",Produccion!$E$6:$E$39),0) -> 15 | F5: =IF(A5="","",IFERROR(C5+D5-E5,"")) -> 0 | G5: 15 | H5: =IF(F5="","",IF(F5<G5,"BAJO","OK")) -> BAJO | I5: 7900 | J5: =IFERROR(F5*I5,"") -> 0
A6: Pan rallado | B6: kg | C6: 25 | D6: =IFERROR(SUMIFS(Compras!$C$5:$C$44,Compras!$B$5:$B$44,A6,Compras!$H$5:$H$44,"Sí"),0) -> 0 | E6: =IFERROR(SUMIF(Produccion!$D$6:$D$39,"Sí",Produccion!$F$6:$F$39),0) -> 10 | F6: =IF(A6="","",IFERROR(C6+D6-E6,"")) -> 15 | G6: 12 | H6: =IF(F6="","",IF(F6<G6,"BAJO","OK")) -> OK | I6: 1512 | J6: =IFERROR(F6*I6,"") -> 22680
A7: Huevo | B7: unidad | C7: 12 | D7: =IFERROR(SUMIFS(Compras!$C$5:$C$44,Compras!$B$5:$B$44,A7,Compras!$H$5:$H$44,"Sí"),0) -> 0 | E7: =IFERROR(SUMIF(Produccion!$D$6:$D$39,"Sí",Produccion!$G$6:$G$39),0) -> 22 | F7: =IF(A7="","",IFERROR(C7+D7-E7,"")) -> -10 | G7: 30 | H7: =IF(F7="","",IF(F7<G7,"BAJO","OK")) -> BAJO | I7: 192 | J7: =IFERROR(F7*I7,"") -> -1920
A8: Sal | B8: Gr | C8: 300 | D8: =IFERROR(SUMIFS(Compras!$C$5:$C$44,Compras!$B$5:$B$44,A8,Compras!$H$5:$H$44,"Sí"),0) -> 0 | E8: =IFERROR(SUMIF(Produccion!$D$6:$D$39,"Sí",Produccion!$H$6:$H$39),0) -> 165 | F8: =IF(A8="","",IFERROR(C8+D8-E8,"")) -> 135 | G8: 150 | H8: =IF(F8="","",IF(F8<G8,"BAJO","OK")) -> BAJO | I8: 2.4 | J8: =IFERROR(F8*I8,"") -> 324
A9: Provenzal | B9: Gr | C9: 600 | D9: =IFERROR(SUMIFS(Compras!$C$5:$C$44,Compras!$B$5:$B$44,A9,Compras!$H$5:$H$44,"Sí"),0) -> 0 | E9: =IFERROR(SUMIF(Produccion!$D$6:$D$39,"Sí",Produccion!$I$6:$I$39),0) -> 125 | F9: =IF(A9="","",IFERROR(C9+D9-E9,"")) -> 475 | G9: 300 | H9: =IF(F9="","",IF(F9<G9,"BAJO","OK")) -> OK | I9: 7.5 | J9: =IFERROR(F9*I9,"") -> 3562.5
A10: Pimenton | B10: Gr | C10: 840 | D10: =IFERROR(SUMIFS(Compras!$C$5:$C$44,Compras!$B$5:$B$44,A10,Compras!$H$5:$H$44,"Sí"),0) -> 0 | E10: =IFERROR(SUMIF(Produccion!$D$6:$D$39,"Sí",Produccion!$J$6:$J$39),0) -> 300 | F10: =IF(A10="","",IFERROR(C10+D10-E10,"")) -> 540 | G10: 160 | H10: =IF(F10="","",IF(F10<G10,"BAJO","OK")) -> OK | I10: 7.8 | J10: =IFERROR(F10*I10,"") -> 4212
A11: Bandejas | B11: Unidad | C11: 100 | D11: =IFERROR(SUMIFS(Compras!$C$5:$C$44,Compras!$B$5:$B$44,A11,Compras!$H$5:$H$44,"Sí"),0) -> 0 | E11: =IFERROR(SUMIF(Produccion!$D$6:$D$39,"Sí",Produccion!$K$6:$K$39),0) -> 24 | F11: =IF(A11="","",IFERROR(C11+D11-E11,"")) -> 76 | G11: 30 | H11: =IF(F11="","",IF(F11<G11,"BAJO","OK")) -> OK | I11: 35.58 | J11: =IFERROR(F11*I11,"") -> 2704.08
A12: Arranque | B12: Unidad | C12: 300 | D12: =IFERROR(SUMIFS(Compras!$C$5:$C$44,Compras!$B$5:$B$44,A12,Compras!$H$5:$H$44,"Sí"),0) -> 0 | E12: =IFERROR(SUMIF(Produccion!$D$6:$D$39,"Sí",Produccion!$L$6:$L$39),0) -> 24 | F12: =IF(A12="","",IFERROR(C12+D12-E12,"")) -> 276 | G12: 30 | H12: =IF(F12="","",IF(F12<G12,"BAJO","OK")) -> OK | I12: 24.13 | J12: =IFERROR(F12*I12,"") -> 6659.88
A13: Folex | B13: unidad | C13: 810 | D13: =IFERROR(SUMIFS(Compras!$C$5:$C$44,Compras!$B$5:$B$44,A13,Compras!$H$5:$H$44,"Sí"),0) -> 0 | E13: =IFERROR(SUMIF(Produccion!$D$6:$D$39,"Sí",Produccion!$M$6:$M$39),0) -> 120 | F13: =IF(A13="","",IFERROR(C13+D13-E13,"")) -> 690 | G13: 90 | H13: =IF(F13="","",IF(F13<G13,"BAJO","OK")) -> OK | I13: 12 | J13: =IFERROR(F13*I13,"") -> 8280
A14: Cofias | B14: unidad | C14: 4 | D14: =IFERROR(SUMIFS(Compras!$C$5:$C$44,Compras!$B$5:$B$44,A14,Compras!$H$5:$H$44,"Sí"),0) -> 0 | E14: =IFERROR(SUMIF(Produccion!$D$6:$D$39,"Sí",Produccion!$N$6:$N$39),0) -> 1 | F14: =IF(A14="","",IFERROR(C14+D14-E14,"")) -> 3 | G14: 2 | H14: =IF(F14="","",IF(F14<G14,"BAJO","OK")) -> OK | I14: 400 | J14: =IFERROR(F14*I14,"") -> 1200
A15: Guantes | B15: unidad | C15: 190 | D15: =IFERROR(SUMIFS(Compras!$C$5:$C$44,Compras!$B$5:$B$44,A15,Compras!$H$5:$H$44,"Sí"),0) -> 0 | E15: =IFERROR(SUMIF(Produccion!$D$6:$D$39,"Sí",Produccion!$O$6:$O$39),0) -> 2 | F15: =IF(A15="","",IFERROR(C15+D15-E15,"")) -> 188 | G15: 12 | H15: =IF(F15="","",IF(F15<G15,"BAJO","OK")) -> OK | I15: 106 | J15: =IFERROR(F15*I15,"") -> 19928
A16: Camiseta | D16: =IFERROR(SUMIFS(Compras!$C$5:$C$44,Compras!$B$5:$B$44,A16,Compras!$H$5:$H$44,"Sí"),0) -> 0 | E16: =IFERROR(SUMIF(Produccion!$D$6:$D$39,"Sí",Produccion!$P$6:$P$39),0) -> 24 | F16: =IF(A16="","",IFERROR(C16+D16-E16,"")) -> -24 | H16: =IF(F16="","",IF(F16<G16,"BAJO","OK")) -> BAJO | J16: =IFERROR(F16*I16,"") -> 0
D17: =IFERROR(SUMIFS(Compras!$C$5:$C$44,Compras!$B$5:$B$44,A17,Compras!$H$5:$H$44,"Sí"),0) -> 0 | E17: =IFERROR(SUMIF(Produccion!$D$6:$D$39,"Sí",Produccion!$Q$6:$Q$39),0) -> 0 | F17: =IF(A17="","",IFERROR(C17+D17-E17,"")) | H17: =IF(F17="","",IF(F17<G17,"BAJO","OK")) | J17: =IFERROR(F17*I17,"")
D18: =IFERROR(SUMIFS(Compras!$C$5:$C$44,Compras!$B$5:$B$44,A18,Compras!$H$5:$H$44,"Sí"),0) -> 0 | E18: =IFERROR(SUMIF(Produccion!$D$6:$D$39,"Sí",Produccion!$R$6:$R$39),0) -> 0 | F18: =IF(A18="","",IFERROR(C18+D18-E18,"")) | H18: =IF(F18="","",IF(F18<G18,"BAJO","OK")) | J18: =IFERROR(F18*I18,"")
D19: =IFERROR(SUMIFS(Compras!$C$5:$C$44,Compras!$B$5:$B$44,A19,Compras!$H$5:$H$44,"Sí"),0) -> 0 | E19: =IFERROR(SUMIF(Produccion!$D$6:$D$39,"Sí",Produccion!$S$6:$S$39),0) -> 0 | F19: =IF(A19="","",IFERROR(C19+D19-E19,"")) | H19: =IF(F19="","",IF(F19<G19,"BAJO","OK")) | J19: =IFERROR(F19*I19,"")
A21: 🟡 Amarillo = completar vos. 🔵 Azul = se calcula solo, no lo edites a mano.

Sheet Ventas
A1: POLLISIMO 🐔 - Ventas y Pedidos
A2: Un renglón por bandeja. Si ya reservaron pero todavía no sabés qué bandeja le vas a dar, cargá Producto + Estado "Reservado" y dejá el Peso en blanco: igual descuenta 1 bandeja del stock disponible. Cuando la entregues, completá el Peso y cambiá el Estado a "Entregado" (el precio se calcula solo y se redondea a $100).
A4: Fecha | B4: Cliente | C4: Producto | D4: Peso (kg) | E4: Precio x Kg | F4: Precio Calculado | G4: Total (redondeado) | H4: Medio de Pago | I4: Estado | J4: Notas
A5: 46217 | B5: Estefania Arregui | C5: Milanesa de pollo | D5: 2.23 | E5: {=IFERROR(INDEX(Productos!$C$5:$C$10,MATCH(C5,Productos!$A$5:$A$10,0)),"")} -> 9500 | F5: =IF(D5="","",IFERROR(D5*E5,"")) -> 21185 | G5: =IF(F5="","",IFERROR(ROUND(F5/100,0)*100,"")) -> 21200 | H5: Transferencia | I5: Entregado
A6: 46217 | B6: Irma | C6: Milanesa de pollo | D6: 2.136 | E6: {=IFERROR(INDEX(Productos!$C$5:$C$10,MATCH(C6,Productos!$A$5:$A$10,0)),"")} -> 9500 | F6: =IF(D6="","",IFERROR(D6*E6,"")) -> 20292 | G6: =IF(F6="","",IFERROR(ROUND(F6/100,0)*100,"")) -> 20300 | H6: Transferencia | I6: Entregado
A7: 46217 | B7: Sofi Magallanes | C7: Milanesa de pollo | D7: 1.115 | E7: {=IFERROR(INDEX(Productos!$C$5:$C$10,MATCH(C7,Productos!$A$5:$A$10,0)),"")} -> 9500 | F7: =IF(D7="","",IFERROR(D7*E7,"")) -> 10592.5 | G7: =IF(F7="","",IFERROR(ROUND(F7/100,0)*100,"")) -> 10600 | H7: Transferencia | I7: Entregado
A8: 46217 | B8: Emi Pereyra | C8: Milanesa de pollo | D8: 1.07 | E8: {=IFERROR(INDEX(Productos!$C$5:$C$10,MATCH(C8,Productos!$A$5:$A$10,0)),"")} -> 9500 | F8: =IF(D8="","",IFERROR(D8*E8,"")) -> 10165 | G8: =IF(F8="","",IFERROR(ROUND(F8/100,0)*100,"")) -> 10200 | H8: Transferencia | I8: Entregado
A9: 46217 | B9: Agus Chacon | C9: Milanesa de pollo | D9: 1.05 | E9: {=IFERROR(INDEX(Productos!$C$5:$C$10,MATCH(C9,Productos!$A$5:$A$10,0)),"")} -> 9500 | F9: =IF(D9="","",IFERROR(D9*E9,"")) -> 9975 | G9: =IF(F9="","",IFERROR(ROUND(F9/100,0)*100,"")) -> 10000 | H9: Efectivo | I9: Entregado
A10: 46217 | B10: Berni | C10: Milanesa de pollo | D10: 1.105 | E10: {=IFERROR(INDEX(Productos!$C$5:$C$10,MATCH(C10,Productos!$A$5:$A$10,0)),"")} -> 9500 | F10: =IF(D10="","",IFERROR(D10*E10,"")) -> 10497.5 | G10: =IF(F10="","",IFERROR(ROUND(F10/100,0)*100,"")) -> 10500 | H10: Efectivo | I10: Entregado
A11: 46217 | B11: Andre | C11: Milanesa de pollo | D11: 1.105 | E11: {=IFERROR(INDEX(Productos!$C$5:$C$10,MATCH(C11,Productos!$A$5:$A$10,0)),"")} -> 9500 | F11: =IF(D11="","",IFERROR(D11*E11,"")) -> 10497.5 | G11: =IF(F11="","",IFERROR(ROUND(F11/100,0)*100,"")) -> 10500 | H11: Efectivo | I11: Entregado
A12: 46217 | B12: Cami Harguyntegui | C12: Milanesa de pollo | D12: 3.117 | E12: {=IFERROR(INDEX(Productos!$C$5:$C$10,MATCH(C12,Productos!$A$5:$A$10,0)),"")} -> 9500 | F12: =IF(D12="","",IFERROR(D12*E12,"")) -> 29611.5 | G12: =IF(F12="","",IFERROR(ROUND(F12/100,0)*100,"")) -> 29600 | H12: Efectivo | I12: Entregado
A13: 46217 | B13: Mari Murue | C13: Milanesa de pollo | D13: 2.03 | E13: {=IFERROR(INDEX(Productos!$C$5:$C$10,MATCH(C13,Productos!$A$5:$A$10,0)),"")} -> 9500 | F13: =IF(D13="","",IFERROR(D13*E13,"")) -> 19285 | G13: =IF(F13="","",IFERROR(ROUND(F13/100,0)*100,"")) -> 19300 | H13: Efectivo | I13: Entregado
A14: 46217 | B14: Cata Domato | C14: Milanesa de pollo | D14: 1.084 | E14: {=IFERROR(INDEX(Productos!$C$5:$C$10,MATCH(C14,Productos!$A$5:$A$10,0)),"")} -> 9500 | F14: =IF(D14="","",IFERROR(D14*E14,"")) -> 10298 | G14: =IF(F14="","",IFERROR(ROUND(F14/100,0)*100,"")) -> 10300 | H14: Transferencia | I14: Entregado
A15: 46217 | B15: Dasil | C15: Milanesa de pollo | D15: 1.05 | E15: {=IFERROR(INDEX(Productos!$C$5:$C$10,MATCH(C15,Productos!$A$5:$A$10,0)),"")} -> 9500 | F15: =IF(D15="","",IFERROR(D15*E15,"")) -> 9975 | G15: =IF(F15="","",IFERROR(ROUND(F15/100,0)*100,"")) -> 10000 | H15: Efectivo | I15: Entregado
A16: 46217 | B16: Ariel Izquierdo | C16: Milanesa de pollo | D16: 1 | E16: {=IFERROR(INDEX(Productos!$C$5:$C$10,MATCH(C16,Productos!$A$5:$A$10,0)),"")} -> 9500 | F16: =IF(D16="","",IFERROR(D16*E16,"")) -> 9500 | G16: =IF(F16="","",IFERROR(ROUND(F16/100,0)*100,"")) -> 9500 | H16: Transferencia | I16: Entregado
... A18: 46218 | B18: Loli Herrera | C18: Milanesa de pollo | D18: 2.215 | E18: {=IFERROR(INDEX(Productos!$C$5:$C$10,MATCH(C18,Productos!$A$5:$A$10,0)),"")} -> 9500 | F18: =IF(D18="","",IFERROR(D18*E18,"")) -> 21042.5 | G18: =IF(F18="","",IFERROR(ROUND(F18/100,0)*100,"")) -> 21000 | H18: Efectivo | I18: Entregado
A19: 46219 | B19: Lili Loker | C19: Milanesa de pollo | E19: {=IFERROR(INDEX(Productos!$C$5:$C$10,MATCH(C19,Productos!$A$5:$A$10,0)),"")} -> 9500 | F19: =IF(D19="","",IFERROR(D19*E19,"")) | G19: =IF(F19="","",IFERROR(ROUND(F19/100,0)*100,"")) | H19: Transferencia | I19: Reservado
A20: 46219 | B20: Fran Isnaldi | C20: Milanesa de pollo | D20: 1.084 | E20: {=IFERROR(INDEX(Productos!$C$5:$C$10,MATCH(C20,Productos!$A$5:$A$10,0)),"")} -> 9500 | F20: =IF(D20="","",IFERROR(D20*E20,"")) -> 10298 | G20: =IF(F20="","",IFERROR(ROUND(F20/100,0)*100,"")) -> 10300 | H20: Transferencia | I20: Entregado
A21: 46219 | B21: Euge Castelli | C21: Milanesa de pollo | D21: 2.263 | E21: {=IFERROR(INDEX(Productos!$C$5:$C$10,MATCH(C21,Productos!$A$5:$A$10,0)),"")} -> 9500 | F21: =IF(D21="","",IFERROR(D21*E21,"")) -> 21498.5 | G21: =IF(F21="","",IFERROR(ROUND(F21/100,0)*100,"")) -> 21500 | H21: Transferencia | I21: Entregado
A22: 46219 | B22: Zul | C22: Milanesa de pollo | D22: 2.189 | E22: {=IFERROR(INDEX(Productos!$C$5:$C$10,MATCH(C22,Productos!$A$5:$A$10,0)),"")} -> 9500 | F22: =IF(D22="","",IFERROR(D22*E22,"")) -> 20795.5 | G22: =IF(F22="","",IFERROR(ROUND(F22/100,0)*100,"")) -> 20800 | H22: Transferencia | I22: Entregado
A23: 46219 | B23: Claudia Biolay | C23: Milanesa de pollo | E23: {=IFERROR(INDEX(Productos!$C$5:$C$10,MATCH(C23,Productos!$A$5:$A$10,0)),"")} -> 9500 | F23: =IF(D23="","",IFERROR(D23*E23,"")) | G23: =IF(F23="","",IFERROR(ROUND(F23/100,0)*100,"")) | H23: Efectivo | I23: Entregado
A24: 46219 | B24: Maria Elva Martinez | C24: Milanesa de pollo | D24: 1.23 | E24: {=IFERROR(INDEX(Productos!$C$5:$C$10,MATCH(C24,Productos!$A$5:$A$10,0)),"")} -> 9500 | F24: =IF(D24="","",IFERROR(D24*E24,"")) -> 11685 | G24: =IF(F24="","",IFERROR(ROUND(F24/100,0)*100,"")) -> 11700 | H24: Transferencia | I24: Entregado
A25: 46221 | B25: Jose | C25: Milanesa de pollo | D25: 4.431 | E25: {=IFERROR(INDEX(Productos!$C$5:$C$10,MATCH(C25,Productos!$A$5:$A$10,0)),"")} -> 9500 | F25: =IF(D25="","",IFERROR(D25*E25,"")) -> 42094.5 | G25: =IF(F25="","",IFERROR(ROUND(F25/100,0)*100,"")) -> 42100 | H25: Transferencia | I25: Entregado
A26: 46221 | B26: Ana Calligo | C26: Milanesa de pollo | D26: 2.105 | E26: {=IFERROR(INDEX(Productos!$C$5:$C$10,MATCH(C26,Productos!$A$5:$A$10,0)),"")} -> 9500 | F26: =IF(D26="","",IFERROR(D26*E26,"")) -> 19997.5 | G26: =IF(F26="","",IFERROR(ROUND(F26/100,0)*100,"")) -> 20000 | H26: Transferencia | I26: Entregado
A27: 46221 | B27: Mari Murue | C27: Milanesa de pollo | D27: 2.2 | E27: {=IFERROR(INDEX(Productos!$C$5:$C$10,MATCH(C27,Productos!$A$5:$A$10,0)),"")} -> 9500 | F27: =IF(D27="","",IFERROR(D27*E27,"")) -> 20900 | G27: =IF(F27="","",IFERROR(ROUND(F27/100,0)*100,"")) -> 20900 | H27: Efectivo | I27: Entregado
A28: 46221 | B28: Georgi | C28: Milanesa de pollo | D28: 1.21 | E28: {=IFERROR(INDEX(Productos!$C$5:$C$10,MATCH(C28,Productos!$A$5:$A$10,0)),"")} -> 9500 | F28: =IF(D28="","",IFERROR(D28*E28,"")) -> 11495 | G28: =IF(F28="","",IFERROR(ROUND(F28/100,0)*100,"")) -> 11500 | I28: Entregado
A29: 46221 | B29: Marce Gonzalez | C29: Milanesa de pollo | D29: 2.263 | E29: {=IFERROR(INDEX(Productos!$C$5:$C$10,MATCH(C29,Productos!$A$5:$A$10,0)),"")} -> 9500 | F29: =IF(D29="","",IFERROR(D29*E29,"")) -> 21498.5 | G29: =IF(F29="","",IFERROR(ROUND(F29/100,0)*100,"")) -> 21500 | H29: Transferencia | I29: Entregado
A30: 46221 | B30: Augusto | C30: Milanesa de pollo | D30: 2.168 | E30: {=IFERROR(INDEX(Productos!$C$5:$C$10,MATCH(C30,Productos!$A$5:$A$10,0)),"")} -> 9500 | F30: =IF(D30="","",IFERROR(D30*E30,"")) -> 20596 | G30: =IF(F30="","",IFERROR(ROUND(F30/100,0)*100,"")) -> 20600 | H30: Transferencia | I30: Entregado
A31: 46221 | B31: Pedro Albornoz | C31: Milanesa de pollo | D31: 1.315 | E31: {=IFERROR(INDEX(Productos!$C$5:$C$10,MATCH(C31,Productos!$A$5:$A$10,0)),"")} -> 9500 | F31: =IF(D31="","",IFERROR(D31*E31,"")) -> 12492.5 | G31: =IF(F31="","",IFERROR(ROUND(F31/100,0)*100,"")) -> 12500 | H31: Transferencia | I31: Entregado
A32: 46221 | B32: Pedro Albornoz | C32: Milanesa de pollo | D32: 2.294 | E32: {=IFERROR(INDEX(Productos!$C$5:$C$10,MATCH(C32,Productos!$A$5:$A$10,0)),"")} -> 9500 | F32: =IF(D32="","",IFERROR(D32*E32,"")) -> 21793 | G32: =IF(F32="","",IFERROR(ROUND(F32/100,0)*100,"")) -> 21800 | H32: Transferencia | I32: Entregado
C33: Milanesa de pollo | E33: {=IFERROR(INDEX(Productos!$C$5:$C$10,MATCH(C33,Productos!$A$5:$A$10,0)),"")} -> 9500 | F33: =IF(D33="","",IFERROR(D33*E33,"")) | G33: =IF(F33="","",IFERROR(ROUND(F33/100,0)*100,""))
C34: Milanesa de pollo | E34: {=IFERROR(INDEX(Productos!$C$5:$C$10,MATCH(C34,Productos!$A$5:$A$10,0)),"")} -> 9500 | F34: =IF(D34="","",IFERROR(D34*E34,"")) | G34: =IF(F34="","",IFERROR(ROUND(F34/100,0)*100,""))
C35: Milanesa de pollo | E35: {=IFERROR(INDEX(Productos!$C$5:$C$10,MATCH(C35,Productos!$A$5:$A$10,0)),"")} -> 9500 | F35: =IF(D35="","",IFERROR(D35*E35,"")) | G35: =IF(F35="","",IFERROR(ROUND(F35/100,0)*100,""))
C36: Milanesa de pollo | E36: {=IFERROR(INDEX(Productos!$C$5:$C$10,MATCH(C36,Productos!$A$5:$A$10,0)),"")} -> 9500 | F36: =IF(D36="","",IFERROR(D36*E36,"")) | G36: =IF(F36="","",IFERROR(ROUND(F36/100,0)*100,""))
C37: Milanesa de pollo | E37: {=IFERROR(INDEX(Productos!$C$5:$C$10,MATCH(C37,Productos!$A$5:$A$10,0)),"")} -> 9500 | F37: =IF(D37="","",IFERROR(D37*E37,"")) | G37: =IF(F37="","",IFERROR(ROUND(F37/100,0)*100,""))
C38: Milanesa de pollo | E38: {=IFERROR(INDEX(Productos!$C$5:$C$10,MATCH(C38,Productos!$A$5:$A$10,0)),"")} -> 9500 | F38: =IF(D38="","",IFERROR(D38*E38,"")) | G38: =IF(F38="","",IFERROR(ROUND(F38/100,0)*100,""))
C39: Milanesa de pollo | E39: {=IFERROR(INDEX(Productos!$C$5:$C$10,MATCH(C39,Productos!$A$5:$A$10,0)),"")} -> 9500 | F39: =IF(D39="","",IFERROR(D39*E39,"")) | G39: =IF(F39="","",IFERROR(ROUND(F39/100,0)*100,""))
C40: Milanesa de pollo | E40: {=IFERROR(INDEX(Productos!$C$5:$C$10,MATCH(C40,Productos!$A$5:$A$10,0)),"")} -> 9500 | F40: =IF(D40="","",IFERROR(D40*E40,"")) | G40: =IF(F40="","",IFERROR(ROUND(F40/100,0)*100,""))
C41: Milanesa de pollo | E41: {=IFERROR(INDEX(Productos!$C$5:$C$10,MATCH(C41,Productos!$A$5:$A$10,0)),"")} -> 9500 | F41: =IF(D41="","",IFERROR(D41*E41,"")) | G41: =IF(F41="","",IFERROR(ROUND(F41/100,0)*100,""))
C42: Milanesa de pollo | E42: {=IFERROR(INDEX(Productos!$C$5:$C$10,MATCH(C42,Productos!$A$5:$A$10,0)),"")} -> 9500 | F42: =IF(D42="","",IFERROR(D42*E42,"")) | G42: =IF(F42="","",IFERROR(ROUND(F42/100,0)*100,""))
...

Sheet Compras
A1: POLLISIMO 🐔 - Compras de Insumos
A2: Registrá cada compra de insumos. El total se calcula solo, y si "Afecta Stock" está en Sí, se suma automáticamente al Stock Actual.
A4: Fecha | B4: Insumo | C4: Cantidad | D4: Costo Unitario | E4: Total | F4: Proveedor | G4: Notas | H4: Afecta Stock
A5: 46214 | B5: Pechuga de pollo | C5: 30 | D5: 7900 | E5: =IFERROR(C5*D5,"") -> 237000 | F5: Fran Mena | G5: Ya contemplada en el Stock Inicial | H5: No
A6: 46214 | B6: Pan rallado | C6: 25 | D6: 1512 | E6: =IFERROR(C6*D6,"") -> 37800 | F6: Fran Mena | H6: No
A7: 46214 | B7: Pan rallado | C7: 20 | D7: 1512 | E7: =IFERROR(C7*D7,"") -> 30240 | F7: Los Abuelitos | H7: No
A8: 46214 | B8: Huevo | C8: 60 | D8: 192 | E8: =IFERROR(C8*D8,"") -> 11520 | F8: Karina | H8: No
A9: 46214 | B9: Provenzal | C9: 1000 | D9: 7.5 | E9: =IFERROR(C9*D9,"") -> 7500 | F9: Karina | H9: No
A10: 46214 | B10: Pimenton | C10: 1000 | D10: 7.8 | E10: =IFERROR(C10*D10,"") -> 7800 | F10: Karina | H10: No
A11: 46214 | B11: Sal | C11: 500 | D11: 2.4 | E11: =IFERROR(C11*D11,"") -> 1200 | F11: Nini | H11: No
A12: 46214 | B12: Bandejas | C12: 73 | D12: 79 | E12: =IFERROR(C12*D12,"") -> 5767 | F12: QSY | H12: No
A13: 46214 | B13: Bandejas | C13: 27 | D13: 86 | E13: =IFERROR(C13*D13,"") -> 2322 | F13: QSY | H13: No
A14: 46214 | B14: Bandejas | C14: 100 | D14: 35.58 | E14: =IFERROR(C14*D14,"") -> 3558 | F14: Navarro | H14: No
A15: 46214 | B15: Folex | C15: 900 | D15: 12 | E15: =IFERROR(C15*D15,"") -> 10800 | F15: QSY | H15: No
A16: 46214 | B16: Guantes | C16: 100 | D16: 131.77 | E16: =IFERROR(C16*D16,"") -> 13177 | F16: QSY | H16: No
A17: 46214 | B17: Guantes | C17: 100 | D17: 106.31 | E17: =IFERROR(C17*D17,"") -> 10631 | F17: Navarro | H17: No
... A19: 46214 | B19: Arranque | C19: 350 | D19: 24 | E19: =IFERROR(C19*D19,"") -> 8400 | F19: Navarro | H19: No
E20: =IFERROR(C20*D20,"") -> 0 | H20: Sí
E21: =IFERROR(C21*D21,"") -> 0 | H21: Sí
E22: =IFERROR(C22*D22,"") -> 0 | H22: Sí
E23: =IFERROR(C23*D23,"") -> 0 | H23: Sí
E24: =IFERROR(C24*D24,"") -> 0 | H24: Sí
E25: =IFERROR(C25*D25,"") -> 0 | H25: Sí
E26: =IFERROR(C26*D26,"") -> 0 | H26: Sí
E27: =IFERROR(C27*D27,"") -> 0 | H27: Sí
E28: =IFERROR(C28*D28,"") -> 0 | H28: Sí
E29: =IFERROR(C29*D29,"") -> 0 | H29: Sí
E30: =IFERROR(C30*D30,"") -> 0 | H30: Sí
E31: =IFERROR(C31*D31,"") -> 0 | H31: Sí
... E44: =IFERROR(C44*D44,"") -> 0 | H44: Sí
A46: Las 15 compras de arriba quedaron marcadas "No" porque ya están reflejadas en tu Stock Inicial de la hoja Stock. Las compras nuevas que cargues de acá en adelante ya vienen marcadas "Sí" y se suman solas al stock.

Sheet Produccion
A1: POLLISIMO 🐔 - Producción
A2: Un renglón por producción. "Afecta Stock" en Sí descuenta los insumos usados del Stock Actual; en No, queda solo como registro (usalo para producciones anteriores que ya están contempladas en tu Stock Inicial). El costo total, costo x kg y costo x bandeja se calculan solos.
A4: Fecha | B4: Producción # | C4: Producto | D4: Afecta Stock | E4: Uso: Pechuga de pollo (kg) | F4: Uso: Pan rallado (kg) | G4: Uso: Huevo (unidad) | H4: Uso: Sal (Gr) | I4: Uso: Provenzal (Gr) | J4: Uso: Pimenton (Gr) | K4: Uso: Bandejas (Unidad) | L4: Uso: Arranque (Unidad) | M4: Uso: Folex (unidad) | N4: Uso: Cofias (unidad) | O4: Uso: Guantes (unidad) | P4: Uso: Camiseta | Q4: Uso: Insumo 13 | R4: Uso: Insumo 14 | S4: Uso: Insumo 15 | T4: Costo Total Insumos | U4: Bandejas Obtenidas | V4: Kilos Obtenidos | W4: Costo x Kg | X4: Costo x Bandeja | Y4: Notas
C5: Milanesa de pollo | D5: Sí | T5: =IF(C5="","",IFERROR(E5*Stock!$I$5+F5*Stock!$I$6+G5*Stock!$I$7+H5*Stock!$I$8+I5*Stock!$I$9+J5*Stock!$I$10+K5*Stock!$I$11+L5*Stock!$I$12+M5*Stock!$I$13+N5*Stock!$I$14+O5*Stock!$I$15+P5*Stock!$I$16+Q5*Stock!$I$17+R5*Stock!$I$18+S5*Stock!$I$19,"")) -> 0 | W5: =IF(C5="","",IFERROR(T5/V5,"")) | X5: =IF(C5="","",IFERROR(T5/U5,""))
A6: 46215 | B6: Prod-01 | C6: Milanesa de pollo | D6: No | E6: 15 | F6: 12 | G6: 24 | H6: 100 | I6: 200 | J6: 80 | K6: 25 | L6: 25 | M6: 75 | N6: 2 | O6: 4 | P6: 25 | T6: =IF(C6="","",IFERROR(E6*Stock!$I$5+F6*Stock!$I$6+G6*Stock!$I$7+H6*Stock!$I$8+I6*Stock!$I$9+J6*Stock!$I$10+K6*Stock!$I$11+L6*Stock!$I$12+M6*Stock!$I$13+N6*Stock!$I$14+O6*Stock!$I$15+P6*Stock!$I$16+Q6*Stock!$I$17+R6*Stock!$I$18+S6*Stock!$I$19,"")) -> 147232.75 | U6: 25 | V6: 27.30 kg | W6: =IF(C6="","",IFERROR(T6/V6,"")) | X6: =IF(C6="","",IFERROR(T6/U6,"")) -> 5889.31
A7: 46217 | B7: Prod-02 | C7: Milanesa de pollo | D7: No | E7: 15 | F7: 8 | G7: 24 | H7: 100 | I7: 200 | J7: 80 | K7: 22 | L7: 22 | M7: 66 | N7: 1 | O7: 4 | P7: 22 | T7: =IF(C7="","",IFERROR(E7*Stock!$I$5+F7*Stock!$I$6+G7*Stock!$I$7+H7*Stock!$I$8+I7*Stock!$I$9+J7*Stock!$I$10+K7*Stock!$I$11+L7*Stock!$I$12+M7*Stock!$I$13+N7*Stock!$I$14+O7*Stock!$I$15+P7*Stock!$I$16+Q7*Stock!$I$17+R7*Stock!$I$18+S7*Stock!$I$19,"")) -> 140497.62 | U7: 22 | V7: 25.00 kg | W7: =IF(C7="","",IFERROR(T7/V7,"")) | X7: =IF(C7="","",IFERROR(T7/U7,"")) -> 6386.2555
A8: 46221 | B8: Prod-03 | C8: Milanesa de pollo | D8: Sí | E8: 15 | F8: 10 | G8: 22 | H8: =115+50 -> 165 | I8: =85+40 -> 125 | J8: =200+100 -> 300 | K8: 24 | L8: 24 | M8: =5*24 -> 120 | N8: 1 | O8: 2 | P8: 24 | T8: =IF(C8="","",IFERROR(E8*Stock!$I$5+F8*Stock!$I$6+G8*Stock!$I$7+H8*Stock!$I$8+I8*Stock!$I$9+J8*Stock!$I$10+K8*Stock!$I$11+L8*Stock!$I$12+M8*Stock!$I$13+N8*Stock!$I$14+O8*Stock!$I$15+P8*Stock!$I$16+Q8*Stock!$I$17+R8*Stock!$I$18+S8*Stock!$I$19,"")) -> 145002.54 | U8: 24 | W8: =IF(C8="","",IFERROR(T8/V8,"")) | X8: =IF(C8="","",IFERROR(T8/U8,"")) -> 6041.7725
C9: Milanesa de pollo | D9: Sí | T9: =IF(C9="","",IFERROR(E9*Stock!$I$5+F9*Stock!$I$6+G9*Stock!$I$7+H9*Stock!$I$8+I9*Stock!$I$9+J9*Stock!$I$10+K9*Stock!$I$11+L9*Stock!$I$12+M9*Stock!$I$13+N9*Stock!$I$14+O9*Stock!$I$15+P9*Stock!$I$16+Q9*Stock!$I$17+R9*Stock!$I$18+S9*Stock!$I$19,"")) -> 0 | W9: =IF(C9="","",IFERROR(T9/V9,"")) | X9: =IF(C9="","",IFERROR(T9/U9,""))
C10: Milanesa de pollo | D10: Sí | T10: =IF(C10="","",IFERROR(E10*Stock!$I$5+F10*Stock!$I$6+G10*Stock!$I$7+H10*Stock!$I$8+I10*Stock!$I$9+J10*Stock!$I$10+K10*Stock!$I$11+L10*Stock!$I$12+M10*Stock!$I$13+N10*Stock!$I$14+O10*Stock!$I$15+P10*Stock!$I$16+Q10*Stock!$I$17+R10*Stock!$I$18+S10*Stock!$I$19,"")) -> 0 | W10: =IF(C10="","",IFERROR(T10/V10,"")) | X10: =IF(C10="","",IFERROR(T10/U10,""))
C11: Milanesa de pollo | D11: Sí | T11: =IF(C11="","",IFERROR(E11*Stock!$I$5+F11*Stock!$I$6+G11*Stock!$I$7+H11*Stock!$I$8+I11*Stock!$I$9+J11*Stock!$I$10+K11*Stock!$I$11+L11*Stock!$I$12+M11*Stock!$I$13+N11*Stock!$I$14+O11*Stock!$I$15+P11*Stock!$I$16+Q11*Stock!$I$17+R11*Stock!$I$18+S11*Stock!$I$19,"")) -> 0 | W11: =IF(C11="","",IFERROR(T11/V11,"")) | X11: =IF(C11="","",IFERROR(T11/U11,""))
C12: Milanesa de pollo | D12: Sí | T12: =IF(C12="","",IFERROR(E12*Stock!$I$5+F12*Stock!$I$6+G12*Stock!$I$7+H12*Stock!$I$8+I12*Stock!$I$9+J12*Stock!$I$10+K12*Stock!$I$11+L12*Stock!$I$12+M12*Stock!$I$13+N12*Stock!$I$14+O12*Stock!$I$15+P12*Stock!$I$16+Q12*Stock!$I$17+R12*Stock!$I$18+S12*Stock!$I$19,"")) -> 0 | W12: =IF(C12="","",IFERROR(T12/V12,"")) | X12: =IF(C12="","",IFERROR(T12/U12,""))
C13: Milanesa de pollo | D13: Sí | T13: =IF(C13="","",IFERROR(E13*Stock!$I$5+F13*Stock!$I$6+G13*Stock!$I$7+H13*Stock!$I$8+I13*Stock!$I$9+J13*Stock!$I$10+K13*Stock!$I$11+L13*Stock!$I$12+M13*Stock!$I$13+N13*Stock!$I$14+O13*Stock!$I$15+P13*Stock!$I$16+Q13*Stock!$I$17+R13*Stock!$I$18+S13*Stock!$I$19,"")) -> 0 | W13: =IF(C13="","",IFERROR(T13/V13,"")) | X13: =IF(C13="","",IFERROR(T13/U13,""))
C14: Milanesa de pollo | D14: Sí | T14: =IF(C14="","",IFERROR(E14*Stock!$I$5+F14*Stock!$I$6+G14*Stock!$I$7+H14*Stock!$I$8+I14*Stock!$I$9+J14*Stock!$I$10+K14*Stock!$I$11+L14*Stock!$I$12+M14*Stock!$I$13+N14*Stock!$I$14+O14*Stock!$I$15+P14*Stock!$I$16+Q14*Stock!$I$17+R14*Stock!$I$18+S14*Stock!$I$19,"")) -> 0 | W14: =IF(C14="","",IFERROR(T14/V14,"")) | X14: =IF(C14="","",IFERROR(T14/U14,""))
C15: Milanesa de pollo | D15: Sí | T15: =IF(C15="","",IFERROR(E15*Stock!$I$5+F15*Stock!$I$6+G15*Stock!$I$7+H15*Stock!$I$8+I15*Stock!$I$9+J15*Stock!$I$10+K15*Stock!$I$11+L15*Stock!$I$12+M15*Stock!$I$13+N15*Stock!$I$14+O15*Stock!$I$15+P15*Stock!$I$16+Q15*Stock!$I$17+R15*Stock!$I$18+S15*Stock!$I$19,"")) -> 0 | W15: =IF(C15="","",IFERROR(T15/V15,"")) | X15: =IF(C15="","",IFERROR(T15/U15,""))
C16: Milanesa de pollo | D16: Sí | T16: =IF(C16="","",IFERROR(E16*Stock!$I$5+F16*Stock!$I$6+G16*Stock!$I$7+H16*Stock!$I$8+I16*Stock!$I$9+J16*Stock!$I$10+K16*Stock!$I$11+L16*Stock!$I$12+M16*Stock!$I$13+N16*Stock!$I$14+O16*Stock!$I$15+P16*Stock!$I$16+Q16*Stock!$I$17+R16*Stock!$I$18+S16*Stock!$I$19,"")) -> 0 | W16: =IF(C16="","",IFERROR(T16/V16,"")) | X16: =IF(C16="","",IFERROR(T16/U16,""))
C17: Milanesa de pollo | D17: Sí | T17: =IF(C17="","",IFERROR(E17*Stock!$I$5+F17*Stock!$I$6+G17*Stock!$I$7+H17*Stock!$I$8+I17*Stock!$I$9+J17*Stock!$I$10+K17*Stock!$I$11+L17*Stock!$I$12+M17*Stock!$I$13+N17*Stock!$I$14+O17*Stock!$I$15+P17*Stock!$I$16+Q17*Stock!$I$17+R17*Stock!$I$18+S17*Stock!$I$19,"")) -> 0 | W17: =IF(C17="","",IFERROR(T17/V17,"")) | X17: =IF(C17="","",IFERROR(T17/U17,""))
C18: Milanesa de pollo | D18: Sí | T18: =IF(C18="","",IFERROR(E18*Stock!$I$5+F18*Stock!$I$6+G18*Stock!$I$7+H18*Stock!$I$8+I18*Stock!$I$9+J18*Stock!$I$10+K18*Stock!$I$11+L18*Stock!$I$12+M18*Stock!$I$13+N18*Stock!$I$14+O18*Stock!$I$15+P18*Stock!$I$16+Q18*Stock!$I$17+R18*Stock!$I$18+S18*Stock!$I$19,"")) -> 0 | W18: =IF(C18="","",IFERROR(T18/V18,"")) | X18: =IF(C18="","",IFERROR(T18/U18,""))
C19: Milanesa de pollo | D19: Sí | T19: =IF(C19="","",IFERROR(E19*Stock!$I$5+F19*Stock!$I$6+G19*Stock!$I$7+H19*Stock!$I$8+I19*Stock!$I$9+J19*Stock!$I$10+K19*Stock!$I$11+L19*Stock!$I$12+M19*Stock!$I$13+N19*Stock!$I$14+O19*Stock!$I$15+P19*Stock!$I$16+Q19*Stock!$I$17+R19*Stock!$I$18+S19*Stock!$I$19,"")) -> 0 | W19: =IF(C19="","",IFERROR(T19/V19,"")) | X19: =IF(C19="","",IFERROR(T19/U19,""))
C20: Milanesa de pollo | D20: Sí | T20: =IF(C20="","",IFERROR(E20*Stock!$I$5+F20*Stock!$I$6+G20*Stock!$I$7+H20*Stock!$I$8+I20*Stock!$I$9+J20*Stock!$I$10+K20*Stock!$I$11+L20*Stock!$I$12+M20*Stock!$I$13+N20*Stock!$I$14+O20*Stock!$I$15+P20*Stock!$I$16+Q20*Stock!$I$17+R20*Stock!$I$18+S20*Stock!$I$19,"")) -> 0 | W20: =IF(C20="","",IFERROR(T20/V20,"")) | X20: =IF(C20="","",IFERROR(T20/U20,""))
... C40: Milanesa de pollo | D40: Sí | T40: =IF(C40="","",IFERROR(E40*Stock!$I$5+F40*Stock!$I$6+G40*Stock!$I$7+H40*Stock!$I$8+I40*Stock!$I$9+J40*Stock!$I$10+K40*Stock!$I$11+L40*Stock!$I$12+M40*Stock!$I$13+N40*Stock!$I$14+O40*Stock!$I$15+P40*Stock!$I$16+Q40*Stock!$I$17+R40*Stock!$I$18+S40*Stock!$I$19,"")) -> 0 | W40: =IF(C40="","",IFERROR(T40/V40,"")) | X40: =IF(C40="","",IFERROR(T40/U40,""))
A42: 🟡 Amarillo = completar vos. 🔵 Azul = se calcula solo. "Afecta Stock" = No para las producciones que ya están contempladas en tu Stock Inicial.
A44: 📦 Stock de Producción disponible (producido menos vendido y reservado)
A45: Producto | B45: Kg Producidos | C45: Kg Vendidos/Reservados | D45: Kg Disponibles | E45: Bandejas Producidas | F45: Band. Vendidas/Reservadas | G45: Bandejas Disponibles
A46: =Productos!A5 -> Milanesa de pollo | B46: =IFERROR(SUMIFS($V$5:$V$40,$C$5:$C$40,A46),0) -> 0 | C46: =IFERROR(SUMIFS(Ventas!$D$5:$D$49,Ventas!$C$5:$C$49,A46,Ventas!$I$5:$I$49,"<>Cancelado",Ventas!$I$5:$I$49,"<>"),0) -> 46.059 | D46: =B46-C46 -> -46.059 | E46: =IFERROR(SUMIFS($U$5:$U$40,$C$5:$C$40,A46),0) -> 71 | F46: =SUMPRODUCT((Ventas!$C$5:$C$49=A46)*(Ventas!$I$5:$I$49<>"Cancelado")*(Ventas!$I$5:$I$49<>"")*((Ventas!$D$5:$D$49="")+(Ventas!$D$5:$D$49<>"")*INT(N(Ventas!$D$5:$D$49)))) -> 44 | G46: =E46-F46 -> 27
A47: =Productos!A6 -> 0 | B47: =IFERROR(SUMIFS($V$5:$V$40,$C$5:$C$40,A47),0) -> 0 | C47: =IFERROR(SUMIFS(Ventas!$D$5:$D$49,Ventas!$C$5:$C$49,A47,Ventas!$I$5:$I$49,"<>Cancelado",Ventas!$I$5:$I$49,"<>"),0) -> 0 | D47: =B47-C47 -> 0 | E47: =IFERROR(SUMIFS($U$5:$U$40,$C$5:$C$40,A47),0) -> 0 | F47: =SUMPRODUCT((Ventas!$C$5:$C$49=A47)*(Ventas!$I$5:$I$49<>"Cancelado")*(Ventas!$I$5:$I$49<>"")*((Ventas!$D$5:$D$49="")+(Ventas!$D$5:$D$49<>"")*INT(N(Ventas!$D$5:$D$49)))) -> 0 | G47: =E47-F47 -> 0
A48: =Productos!A7 -> 0 | B48: =IFERROR(SUMIFS($V$5:$V$40,$C$5:$C$40,A48),0) -> 0 | C48: =IFERROR(SUMIFS(Ventas!$D$5:$D$49,Ventas!$C$5:$C$49,A48,Ventas!$I$5:$I$49,"<>Cancelado",Ventas!$I$5:$I$49,"<>"),0) -> 0 | D48: =B48-C48 -> 0 | E48: =IFERROR(SUMIFS($U$5:$U$40,$C$5:$C$40,A48),0) -> 0 | F48: =SUMPRODUCT((Ventas!$C$5:$C$49=A48)*(Ventas!$I$5:$I$49<>"Cancelado")*(Ventas!$I$5:$I$49<>"")*((Ventas!$D$5:$D$49="")+(Ventas!$D$5:$D$49<>"")*INT(N(Ventas!$D$5:$D$49)))) -> 0 | G48: =E48-F48 -> 0
A49: =Productos!A8 -> 0 | B49: =IFERROR(SUMIFS($V$5:$V$40,$C$5:$C$40,A49),0) -> 0 | C49: =IFERROR(SUMIFS(Ventas!$D$5:$D$49,Ventas!$C$5:$C$49,A49,Ventas!$I$5:$I$49,"<>Cancelado",Ventas!$I$5:$I$49,"<>"),0) -> 0 | D49: =B49-C49 -> 0 | E49: =IFERROR(SUMIFS($U$5:$U$40,$C$5:$C$40,A49),0) -> 0 | F49: =SUMPRODUCT((Ventas!$C$5:$C$49=A49)*(Ventas!$I$5:$I$49<>"Cancelado")*(Ventas!$I$5:$I$49<>"")*((Ventas!$D$5:$D$49="")+(Ventas!$D$5:$D$49<>"")*INT(N(Ventas!$D$5:$D$49)))) -> 0 | G49: =E49-F49 -> 0
A50: =Productos!A9 -> 0 | B50: =IFERROR(SUMIFS($V$5:$V$40,$C$5:$C$40,A50),0) -> 0 | C50: =IFERROR(SUMIFS(Ventas!$D$5:$D$49,Ventas!$C$5:$C$49,A50,Ventas!$I$5:$I$49,"<>Cancelado",Ventas!$I$5:$I$49,"<>"),0) -> 0 | D50: =B50-C50 -> 0 | E50: =IFERROR(SUMIFS($U$5:$U$40,$C$5:$C$40,A50),0) -> 0 | F50: =SUMPRODUCT((Ventas!$C$5:$C$49=A50)*(Ventas!$I$5:$I$49<>"Cancelado")*(Ventas!$I$5:$I$49<>"")*((Ventas!$D$5:$D$49="")+(Ventas!$D$5:$D$49<>"")*INT(N(Ventas!$D$5:$D$49)))) -> 0 | G50: =E50-F50 -> 0
A51: =Productos!A10 -> 0 | B51: =IFERROR(SUMIFS($V$5:$V$40,$C$5:$C$40,A51),0) -> 0 | C51: =IFERROR(SUMIFS(Ventas!$D$5:$D$49,Ventas!$C$5:$C$49,A51,Ventas!$I$5:$I$49,"<>Cancelado",Ventas!$I$5:$I$49,"<>"),0) -> 0 | D51: =B51-C51 -> 0 | E51: =IFERROR(SUMIFS($U$5:$U$40,$C$5:$C$40,A51),0) -> 0 | F51: =SUMPRODUCT((Ventas!$C$5:$C$49=A51)*(Ventas!$I$5:$I$49<>"Cancelado")*(Ventas!$I$5:$I$49<>"")*((Ventas!$D$5:$D$49="")+(Ventas!$D$5:$D$49<>"")*INT(N(Ventas!$D$5:$D$49)))) -> 0 | G51: =E51-F51 -> 0
